Workbook

Sheet Instructions
A1: TALARIA DASHBOARD — EXHAUSTIVE UAT TRACKER
A3: Scope | B3: Every field, configuration, validation path, visual/layout check, normal + edge + extreme inputs.
A4: Testers | B4: 2 people — Tester A (Sections 1–2), Tester B (Sections 3–4), then swap.
A5: Categories | B5: Normal | Edge | Extreme | Configuration | Input matrix | Logic | Structure
A6: Columns | B6: Test Input = exact value to enter; Expected Result = pass criteria.
A7: Result | B7: ☑ Pass | ☐ Fail | ⚠ Partial | — Not tested
A8: P0 | B8: Launch blocker — stop and report immediately.
B9: Total steps: 541 across 4 sections
A10: 1 — Strategies | B10: Phases 1–13, 44, 49, 50, 52: Bank + Builder + abuse/responsive
A11: 2 — Sessions | B11: Phases 14–24, 42–43, 49–51: List + Modal + mode matrix + toggles
A12: 3 — Trades | B12: Phases 25–34, 45–47, 49–50, 53: Table + validations + import/export
A13: 4 — Sources | B13: Phases 35–41, 48, 49–50, 54–55: Library + compare + state machine

Sheet QA Tracker
A1: Step # | B1: Section | C1: Phase | D1: Phase Name | E1: Category | F1: Priority | G1: What to Do | H1: Test Input | I1: Expected Result | J1: Tester A | K1: Tester B | L1: Issue? | M1: Comments
A2: 1 | B2: 1 — Strategies | C2: 1 | D2: Strategy Bank — Access & Shell | E2: Structure | F2: P0 | G2: Open /dashboard/ while logged in. | H2: — | I2: Dashboard shell loads; left nav visible. | J2: — Not tested | K2: — Not tested | L2: — Not tested
A3: 2 | B3: 1 — Strategies | C3: 1 | D3: Strategy Bank — Access & Shell | E3: Structure | F3: P0 | G3: Navigate to Strategies via left nav. | H3: — | I3: Strategy Bank page; header title visible. | J3: — Not tested | K3: — Not tested | L3: — Not tested
A4: 3 | B4: 1 — Strategies | C4: 1 | D4: Strategy Bank — Access & Shell | E4: Structure | F4: P1 | G4: Refresh browser on Strategy Bank. | H4: — | I4: Page reloads; strategies list persists. | J4: — Not tested | K4: — Not tested | L4: — Not tested
A5: 4 | B5: 1 — Strategies | C5: 1 | D5: Strategy Bank — Access & Shell | E5: Structure | F5: P1 | G5: Resize browser: 1920px, 1366px, 1024px widths. | H5: 3 widths | I5: Layout does not overlap or clip header/controls. | J5: — Not tested | K5: — Not tested | L5: — Not tested
A6: 5 | B6: 1 — Strategies | C6: 1 | D6: Strategy Bank — Access & Shell | E6: Structure | F6: P2 | G6: Zoom browser 90% and 110%. | H6: — | I6: Cards/rows remain readable; no broken dropdowns. | J6: — Not tested | K6: — Not tested | L6: — Not tested
A7: 6 | B7: 1 — Strategies | C7: 2 | D7: Strategy Bank — Controls & Empty States | E7: Normal | F7: P0 | G7: Click Build Strategy. | H7: — | I7: Template picker OR builder opens. | J7: — Not tested | K7: — Not tested | L7: — Not tested
A8: 7 | B8: 1 — Strategies | C8: 2 | D8: Strategy Bank — Controls & Empty States | E8: Normal | F8: P1 | G8: Toggle Cards view. | H8: — | I8: Grid of cards with consistent height. | J8: — Not tested | K8: — Not tested | L8: — Not tested
A9: 8 | B9: 1 — Strategies | C9: 2 | D9: Strategy Bank — Controls & Empty States | E9: Normal | F9: P1 | G9: Toggle Rows view. | H9: — | I9: Table rows align; columns readable. | J9: — Not tested | K9: — Not tested | L9: — Not tested
A10: 9 | B10: 1 — Strategies | C10: 2 | D10: Strategy Bank — Controls & Empty States | E10: Normal | F10: P1 | G10: Search partial strategy name. | H10: e.g. 'mom' | I10: Only matching strategies shown. | J10: — Not tested | K10: — Not tested | L10: — Not tested
A11: 10 | B11: 1 — Strategies | C11: 2 | D11: Strategy Bank — Controls & Empty States | E11: Normal | F11: P1 | G11: Search by tag text. | H11: e.g. 'Scalping' | I11: Strategies with that tag appear. | J11: — Not tested | K11: — Not tested | L11: — Not tested
A12: 11 | B12: 1 — Strategies | C12: 2 | D12: Strategy Bank — Controls & Empty States | E12: Normal | F12: P1 | G12: Search gibberish. | H12: zzzznotfound | I12: Empty/no-match message; no crash. | J12: — Not tested | K12: — Not tested | L12: — Not tested
A13: 12 | B13: 1 — Strategies | C13: 2 | D13: Strategy Bank — Controls & Empty States | E13: Normal | F13: P2 | G13: Clear search with ×. | H13: — | I13: Full list restored. | J13: — Not tested | K13: — Not tested | L13: — Not tested
... A45: 44 | B45: 1 — Strategies | C45: 5 | D45: Strategy Builder — Wizard Shell | E45: Logic | F45: P0 | G45: Back from Step 3 → Step 2 → data preserved. | H45: — | I45: No data loss. | J45: — Not tested | K45: — Not tested | L45: — Not tested
A46: 45 | B46: 1 — Strategies | C46: 6 | D46: Builder Step 1 — Strategy Name | E46: Input matrix | F46: P0 | G46: Leave name empty → Next. | I46: Blocked; red border on name field. | J46: — Not tested | K46: — Not tested | L46: — Not tested
A47: 46 | B47: 1 — Strategies | C47: 6 | D47: Builder Step 1 — Strategy Name | E47: Input matrix | F47: P1 | G47: Name = 1 character. | H47: A | I47: Accepts; can proceed if markets+TF set. | J47: — Not tested | K47: — Not tested | L47: — Not tested
A48: 47 | B48: 1 — Strategies | C48: 6 | D48: Builder Step 1 — Strategy Name | E48: Input matrix | F48: P1 | G48: Name = 80 characters (max). | H48: 80×A | I48: Accepts; no truncate in input. | J48: — Not tested | K48: — Not tested | L48: — Not tested
A49: 48 | B49: 1 — Strategies | C49: 6 | D49: Builder Step 1 — Strategy Name | E49: Input matrix | F49: P1 | G49: Name = 81+ characters. | H49: 81×A | I49: Input stops at 80 (maxLength). | J49: — Not tested | K49: — Not tested | L49: — Not tested
A50: 49 | B50: 1 — Strategies | C50: 6 | D50: Builder Step 1 — Strategy Name | E50: Input matrix | F50: P0 | G50: Name = only spaces. | I50: Treated as empty; blocked. | J50: — Not tested | K50: — Not tested | L50: — Not tested
A51: 50 | B51: 1 — Strategies | C51: 6 | D51: Builder Step 1 — Strategy Name | E51: Input matrix | F51: P2 | G51: Name with emoji inline. | H51: Rocket 🚀 Scalp | I51: Displays correctly on card. | J51: — Not tested | K51: — Not tested | L51: — Not tested
A52: 51 | B52: 1 — Strategies | C52: 6 | D52: Builder Step 1 — Strategy Name | E52: Input matrix | F52: P0 | G52: Name special chars. | H52: Test <>&"' | I52: Displays literally; no HTML injection. | J52: — Not tested | K52: — Not tested | L52: — Not tested
A53: 52 | B53: 1 — Strategies | C53: 6 | D53: Builder Step 1 — Strategy Name | E53: Input matrix | F53: P2 | G53: Name Arabic. | H53: استراتيجية الذهب | I53: RTL displays correctly. | J53: — Not tested | K53: — Not tested | L53: — Not tested
A54: 53 | B54: 1 — Strategies | C54: 6 | D54: Builder Step 1 — Strategy Name | E54: Input matrix | F54: P2 | G54: Name duplicate of existing. | H54: same as another | I54: Allowed (duplicates OK) or warn — note behavior. | J54: — Not tested | K54: — Not tested | L54: — Not tested
A55: 54 | B55: 1 — Strategies | C55: 6 | D55: Builder Step 1 — Description & Emoji | E55: Input matrix | F55: P1 | G55: Description empty. | H55: — | I55: Allowed; optional field. | J55: — Not tested | K55: — Not tested | L55: — Not tested
A56: 55 | B56: 1 — Strategies | C56: 6 | D56: Builder Step 1 — Description & Emoji | E56: Input matrix | F56: P1 | G56: Description 500 chars (max). | H56: 500 chars | I56: Counter shows 500/500; accepts. | J56: — Not tested | K56: — Not tested | L56: — Not tested
A57: 56 | B57: 1 — Strategies | C57: 6 | D57: Builder Step 1 — Description & Emoji | E57: Input matrix | F57: P1 | G57: Description 501+ chars. | H57: paste 501 | I57: Blocked at 500 maxLength. | J57: — Not tested | K57: — Not tested | L57: — Not tested
A58: 57 | B58: 1 — Strategies | C58: 6 | D58: Builder Step 1 — Description & Emoji | E58: Input matrix | F58: P2 | G58: Description with newlines. | H58: line1\nline2 | I58: Multiline displays on card/review. | J58: — Not tested | K58: — Not tested | L58: — Not tested
A59: 58 | B59: 1 — Strategies | C59: 6 | D59: Builder Step 1 — Description & Emoji | E59: Input matrix | F59: P1 | G59: Open emoji picker → browse Finance category. | H59: — | I59: Emoji grid loads. | J59: — Not tested | K59: — Not tested | L59: — Not tested
A60: 59 | B60: 1 — Strategies | C60: 6 | D60: Builder Step 1 — Description & Emoji | E60: Input matrix | F60: P2 | G60: Search emoji picker. | H60: chart | I60: Filters emoji list. | J60: — Not tested | K60: — Not tested | L60: — Not tested
A61: 60 | B61: 1 — Strategies | C61: 6 | D61: Builder Step 1 — Description & Emoji | E61: Input matrix | F61: P1 | G61: Select emoji → appears on button. | H61: 📈 | I61: Emoji shows on picker button. | J61: — Not tested | K61: — Not tested | L61: — Not tested
A62: 61 | B62: 1 — Strategies | C62: 6 | D62: Builder Step 1 — Description & Emoji | E62: Input matrix | F62: P2 | G62: Remove emoji via × on button. | H62: — | I62: Emoji clears. | J62: — Not tested | K62: — Not tested | L62: — Not tested
... A183: 182 | B183: 2 — Sessions | C183: 17 | D183: New Session — Kind Picker | E183: Configuration | F183: P2 | G183: Link broker — Coming Soon. | H183: — | I183: Disabled or blocked. | J183: — Not tested | K183: — Not tested | L183: — Not tested
A184: 183 | B184: 2 — Sessions | C184: 18 | D184: Add Session — Session Info Fields | E184: Input matrix | F184: P0 | G184: Session name empty. | I184: Save/Start disabled. | J184: — Not tested | K184: — Not tested | L184: — Not tested
A185: 184 | B185: 2 — Sessions | C185: 18 | D185: Add Session — Session Info Fields | E185: Input matrix | F185: P2 | G185: Session name 1 char. | H185: A | I185: Accepted. | J185: — Not tested | K185: — Not tested | L185: — Not tested
A186: 185 | B186: 2 — Sessions | C186: 18 | D186: Add Session — Session Info Fields | E186: Input matrix | F186: P2 | G186: Session name very long (200+ chars). | H186: long | I186: Truncated or accepted — note limit. | J186: — Not tested | K186: — Not tested | L186: — Not tested
A187: 186 | B187: 2 — Sessions | C187: 18 | D187: Add Session — Session Info Fields | E187: Input matrix | F187: P1 | G187: Session name special chars. | H187: Test & < > | I187: Displays safely. | J187: — Not tested | K187: — Not tested | L187: — Not tested
A188: 187 | B188: 2 — Sessions | C188: 18 | D188: Add Session — Session Info Fields | E188: Input matrix | F188: P1 | G188: Strategy = None. | H188: None | I188: Session saves without linked strategy. | J188: — Not tested | K188: — Not tested | L188: — Not tested
A189: 188 | B189: 2 — Sessions | C189: 18 | D189: Add Session — Session Info Fields | E189: Input matrix | F189: P1 | G189: Strategy = pick each of your strategies. | H189: each | I189: Strategy name links. | J189: — Not tested | K189: — Not tested | L189: — Not tested
A190: 189 | B190: 2 — Sessions | C190: 18 | D190: Add Session — Session Info Fields | E190: Input matrix | F190: P2 | G190: New Strategy shortcut. | H190: — | I190: Navigates to strategy create. | J190: — Not tested | K190: — Not tested | L190: — Not tested
A191: 190 | B191: 2 — Sessions | C191: 18 | D191: Add Session — Session Info Fields | E191: Input matrix | F191: P2 | G191: Description empty vs filled. | H191: paragraph | I191: Saves both cases. | J191: — Not tested | K191: — Not tested | L191: — Not tested
...

Sheet Summary
A1: Phase | B1: Phase Name | C1: Section | D1: Steps | E1: P0 | F1: A Pass | G1: B Pass | H1: Issues
A2: 1 | B2: Strategy Bank — Access & Shell | C2: 1 — Strategies | D2: =COUNTIFS('QA Tracker'!C:C,1) | E2: =COUNTIFS('QA Tracker'!C:C,1,'QA Tracker'!F:F,"P0") | F2: =COUNTIFS('QA Tracker'!C:C,1,'QA Tracker'!J:J,"☑ Pass") | G2: =COUNTIFS('QA Tracker'!C:C,1,'QA Tracker'!I:I,"☑ Pass") | H2: =COUNTIFS('QA Tracker'!C:C,1,'QA Tracker'!L:L,"☑ Yes")
A3: 2 | B3: Strategy Bank — Controls & Empty States | C3: 1 — Strategies | D3: =COUNTIFS('QA Tracker'!C:C,2) | E3: =COUNTIFS('QA Tracker'!C:C,2,'QA Tracker'!F:F,"P0") | F3: =COUNTIFS('QA Tracker'!C:C,2,'QA Tracker'!J:J,"☑ Pass") | G3: =COUNTIFS('QA Tracker'!C:C,2,'QA Tracker'!I:I,"☑ Pass") | H3: =COUNTIFS('QA Tracker'!C:C,2,'QA Tracker'!L:L,"☑ Yes")
A4: 3 | B4: Strategy Bank — Card/Row Content & Visuals | C4: 1 — Strategies | D4: =COUNTIFS('QA Tracker'!C:C,3) | E4: =COUNTIFS('QA Tracker'!C:C,3,'QA Tracker'!F:F,"P0") | F4: =COUNTIFS('QA Tracker'!C:C,3,'QA Tracker'!J:J,"☑ Pass") | G4: =COUNTIFS('QA Tracker'!C:C,3,'QA Tracker'!I:I,"☑ Pass") | H4: =COUNTIFS('QA Tracker'!C:C,3,'QA Tracker'!L:L,"☑ Yes")
A5: 4 | B5: Template Picker | C5: 1 — Strategies | D5: =COUNTIFS('QA Tracker'!C:C,4) | E5: =COUNTIFS('QA Tracker'!C:C,4,'QA Tracker'!F:F,"P0") | F5: =COUNTIFS('QA Tracker'!C:C,4,'QA Tracker'!J:J,"☑ Pass") | G5: =COUNTIFS('QA Tracker'!C:C,4,'QA Tracker'!I:I,"☑ Pass") | H5: =COUNTIFS('QA Tracker'!C:C,4,'QA Tracker'!L:L,"☑ Yes")
A6: 5 | B6: Strategy Builder — Wizard Shell | C6: 1 — Strategies | D6: =COUNTIFS('QA Tracker'!C:C,5) | E6: =COUNTIFS('QA Tracker'!C:C,5,'QA Tracker'!F:F,"P0") | F6: =COUNTIFS('QA Tracker'!C:C,5,'QA Tracker'!J:J,"☑ Pass") | G6: =COUNTIFS('QA Tracker'!C:C,5,'QA Tracker'!I:I,"☑ Pass") | H6: =COUNTIFS('QA Tracker'!C:C,5,'QA Tracker'!L:L,"☑ Yes")
A7: 6 | B7: Builder Step 1 — Strategy Name | C7: 1 — Strategies | D7: =COUNTIFS('QA Tracker'!C:C,6) | E7: =COUNTIFS('QA Tracker'!C:C,6,'QA Tracker'!F:F,"P0") | F7: =COUNTIFS('QA Tracker'!C:C,6,'QA Tracker'!J:J,"☑ Pass") | G7: =COUNTIFS('QA Tracker'!C:C,6,'QA Tracker'!I:I,"☑ Pass") | H7: =COUNTIFS('QA Tracker'!C:C,6,'QA Tracker'!L:L,"☑ Yes")
A8: 7 | B8: Builder Step 1 — Tags | C8: 1 — Strategies | D8: =COUNTIFS('QA Tracker'!C:C,7) | E8: =COUNTIFS('QA Tracker'!C:C,7,'QA Tracker'!F:F,"P0") | F8: =COUNTIFS('QA Tracker'!C:C,7,'QA Tracker'!J:J,"☑ Pass") | G8: =COUNTIFS('QA Tracker'!C:C,7,'QA Tracker'!I:I,"☑ Pass") | H8: =COUNTIFS('QA Tracker'!C:C,7,'QA Tracker'!L:L,"☑ Yes")
A9: 8 | B9: Builder Step 1 — Markets & Instruments | C9: 1 — Strategies | D9: =COUNTIFS('QA Tracker'!C:C,8) | E9: =COUNTIFS('QA Tracker'!C:C,8,'QA Tracker'!F:F,"P0") | F9: =COUNTIFS('QA Tracker'!C:C,8,'QA Tracker'!J:J,"☑ Pass") | G9: =COUNTIFS('QA Tracker'!C:C,8,'QA Tracker'!I:I,"☑ Pass") | H9: =COUNTIFS('QA Tracker'!C:C,8,'QA Tracker'!L:L,"☑ Yes")
A10: 9 | B10: Builder Step 1 — Timeframes | C10: 1 — Strategies | D10: =COUNTIFS('QA Tracker'!C:C,9) | E10: =COUNTIFS('QA Tracker'!C:C,9,'QA Tracker'!F:F,"P0") | F10: =COUNTIFS('QA Tracker'!C:C,9,'QA Tracker'!J:J,"☑ Pass") | G10: =COUNTIFS('QA Tracker'!C:C,9,'QA Tracker'!I:I,"☑ Pass") | H10: =COUNTIFS('QA Tracker'!C:C,9,'QA Tracker'!L:L,"☑ Yes")
A11: 10 | B11: Builder Step 1 — Cover Images | C11: 1 — Strategies | D11: =COUNTIFS('QA Tracker'!C:C,10) | E11: =COUNTIFS('QA Tracker'!C:C,10,'QA Tracker'!F:F,"P0") | F11: =COUNTIFS('QA Tracker'!C:C,10,'QA Tracker'!J:J,"☑ Pass") | G11: =COUNTIFS('QA Tracker'!C:C,10,'QA Tracker'!I:I,"☑ Pass") | H11: =COUNTIFS('QA Tracker'!C:C,10,'QA Tracker'!L:L,"☑ Yes")
A12: 11 | B12: Builder Step 2 — Canvas Structure | C12: 1 — Strategies | D12: =COUNTIFS('QA Tracker'!C:C,11) | E12: =COUNTIFS('QA Tracker'!C:C,11,'QA Tracker'!F:F,"P0") | F12: =COUNTIFS('QA Tracker'!C:C,11,'QA Tracker'!J:J,"☑ Pass") | G12: =COUNTIFS('QA Tracker'!C:C,11,'QA Tracker'!I:I,"☑ Pass") | H12: =COUNTIFS('QA Tracker'!C:C,11,'QA Tracker'!L:L,"☑ Yes")
A13: 12 | B13: Builder Step 3 — Trade Tags | C13: 1 — Strategies | D13: =COUNTIFS('QA Tracker'!C:C,12) | E13: =COUNTIFS('QA Tracker'!C:C,12,'QA Tracker'!F:F,"P0") | F13: =COUNTIFS('QA Tracker'!C:C,12,'QA Tracker'!J:J,"☑ Pass") | G13: =COUNTIFS('QA Tracker'!C:C,12,'QA Tracker'!I:I,"☑ Pass") | H13: =COUNTIFS('QA Tracker'!C:C,12,'QA Tracker'!L:L,"☑ Yes")
A14: 13 | B14: Builder Step 4 — Review & Persistence | C14: 1 — Strategies | D14: =COUNTIFS('QA Tracker'!C:C,13) | E14: =COUNTIFS('QA Tracker'!C:C,13,'QA Tracker'!F:F,"P0") | F14: =COUNTIFS('QA Tracker'!C:C,13,'QA Tracker'!J:J,"☑ Pass") | G14: =COUNTIFS('QA Tracker'!C:C,13,'QA Tracker'!I:I,"☑ Pass") | H14: =COUNTIFS('QA Tracker'!C:C,13,'QA Tracker'!L:L,"☑ Yes")
A15: 14 | B15: Sessions Page — Shell & Stats | C15: 2 — Sessions | D15: =COUNTIFS('QA Tracker'!C:C,14) | E15: =COUNTIFS('QA Tracker'!C:C,14,'QA Tracker'!F:F,"P0") | F15: =COUNTIFS('QA Tracker'!C:C,14,'QA Tracker'!J:J,"☑ Pass") | G15: =COUNTIFS('QA Tracker'!C:C,14,'QA Tracker'!I:I,"☑ Pass") | H15: =COUNTIFS('QA Tracker'!C:C,14,'QA Tracker'!L:L,"☑ Yes")
A16: 15 | B16: Sessions — Filters & Sort | C16: 2 — Sessions | D16: =COUNTIFS('QA Tracker'!C:C,15) | E16: =COUNTIFS('QA Tracker'!C:C,15,'QA Tracker'!F:F,"P0") | F16: =COUNTIFS('QA Tracker'!C:C,15,'QA Tracker'!J:J,"☑ Pass") | G16: =COUNTIFS('QA Tracker'!C:C,15,'QA Tracker'!I:I,"☑ Pass") | H16: =COUNTIFS('QA Tracker'!C:C,15,'QA Tracker'!L:L,"☑ Yes")
A17: 16 | B17: Sessions — Row Actions by State | C17: 2 — Sessions | D17: =COUNTIFS('QA Tracker'!C:C,16) | E17: =COUNTIFS('QA Tracker'!C:C,16,'QA Tracker'!F:F,"P0") | F17: =COUNTIFS('QA Tracker'!C:C,16,'QA Tracker'!J:J,"☑ Pass") | G17: =COUNTIFS('QA Tracker'!C:C,16,'QA Tracker'!I:I,"☑ Pass") | H17: =COUNTIFS('QA Tracker'!C:C,16,'QA Tracker'!L:L,"☑ Yes")
A18: 17 | B18: New Session — Kind Picker | C18: 2 — Sessions | D18: =COUNTIFS('QA Tracker'!C:C,17) | E18: =COUNTIFS('QA Tracker'!C:C,17,'QA Tracker'!F:F,"P0") | F18: =COUNTIFS('QA Tracker'!C:C,17,'QA Tracker'!J:J,"☑ Pass") | G18: =COUNTIFS('QA Tracker'!C:C,17,'QA Tracker'!I:I,"☑ Pass") | H18: =COUNTIFS('QA Tracker'!C:C,17,'QA Tracker'!L:L,"☑ Yes")
A19: 18 | B19: Add Session — Session Info Fields | C19: 2 — Sessions | D19: =COUNTIFS('QA Tracker'!C:C,18) | E19: =COUNTIFS('QA Tracker'!C:C,18,'QA Tracker'!F:F,"P0") | F19: =COUNTIFS('QA Tracker'!C:C,18,'QA Tracker'!J:J,"☑ Pass") | G19: =COUNTIFS('QA Tracker'!C:C,18,'QA Tracker'!I:I,"☑ Pass") | H19: =COUNTIFS('QA Tracker'!C:C,18,'QA Tracker'!L:L,"☑ Yes")
A20: 19 | B20: Add Session — Asset Class & Symbols | C20: 2 — Sessions | D20: =COUNTIFS('QA Tracker'!C:C,19) | E20: =COUNTIFS('QA Tracker'!C:C,19,'QA Tracker'!F:F,"P0") | F20: =COUNTIFS('QA Tracker'!C:C,19,'QA Tracker'!J:J,"☑ Pass") | G20: =COUNTIFS('QA Tracker'!C:C,19,'QA Tracker'!I:I,"☑ Pass") | H20: =COUNTIFS('QA Tracker'!C:C,19,'QA Tracker'!L:L,"☑ Yes")
A21: 20 | B21: Add Session — Timeframe & Replay | C21: 2 — Sessions | D21: =COUNTIFS('QA Tracker'!C:C,20) | E21: =COUNTIFS('QA Tracker'!C:C,20,'QA Tracker'!F:F,"P0") | F21: =COUNTIFS('QA Tracker'!C:C,20,'QA Tracker'!J:J,"☑ Pass") | G21: =COUNTIFS('QA Tracker'!C:C,20,'QA Tracker'!I:I,"☑ Pass") | H21: =COUNTIFS('QA Tracker'!C:C,20,'QA Tracker'!L:L,"☑ Yes")
A22: 21 | B22: Add Session — Date Range | C22: 2 — Sessions | D22: =COUNTIFS('QA Tracker'!C:C,21) | E22: =COUNTIFS('QA Tracker'!C:C,21,'QA Tracker'!F:F,"P0") | F22: =COUNTIFS('QA Tracker'!C:C,21,'QA Tracker'!J:J,"☑ Pass") | G22: =COUNTIFS('QA Tracker'!C:C,21,'QA Tracker'!I:I,"☑ Pass") | H22: =COUNTIFS('QA Tracker'!C:C,21,'QA Tracker'!L:L,"☑ Yes")
A23: 22 | B23: Add Session — Account & Costs | C23: 2 — Sessions | D23: =COUNTIFS('QA Tracker'!C:C,22) | E23: =COUNTIFS('QA Tracker'!C:C,22,'QA Tracker'!F:F,"P0") | F23: =COUNTIFS('QA Tracker'!C:C,22,'QA Tracker'!J:J,"☑ Pass") | G23: =COUNTIFS('QA Tracker'!C:C,22,'QA Tracker'!I:I,"☑ Pass") | H23: =COUNTIFS('QA Tracker'!C:C,22,'QA Tracker'!L:L,"☑ Yes")
A24: 23 | B24: Add Session — Prop Firm Mode | C24: 2 — Sessions | D24: =COUNTIFS('QA Tracker'!C:C,23) | E24: =COUNTIFS('QA Tracker'!C:C,23,'QA Tracker'!F:F,"P0") | F24: =COUNTIFS('QA Tracker'!C:C,23,'QA Tracker'!J:J,"☑ Pass") | G24: =COUNTIFS('QA Tracker'!C:C,23,'QA Tracker'!I:I,"☑ Pass") | H24: =COUNTIFS('QA Tracker'!C:C,23,'QA Tracker'!L:L,"☑ Yes")
A25: 24 | B25: Add Session — Save, Start, Limits | C25: 2 — Sessions | D25: =COUNTIFS('QA Tracker'!C:C,24) | E25: =COUNTIFS('QA Tracker'!C:C,24,'QA Tracker'!F:F,"P0") | F25: =COUNTIFS('QA Tracker'!C:C,24,'QA Tracker'!J:J,"☑ Pass") | G25: =COUNTIFS('QA Tracker'!C:C,24,'QA Tracker'!I:I,"☑ Pass") | H25: =COUNTIFS('QA Tracker'!C:C,24,'QA Tracker'!L:L,"☑ Yes")
A26: 25 | B26: Trades Page — Shell & Header | C26: 3 — Trades | D26: =COUNTIFS('QA Tracker'!C:C,25) | E26: =COUNTIFS('QA Tracker'!C:C,25,'QA Tracker'!F:F,"P0") | F26: =COUNTIFS('QA Tracker'!C:C,25,'QA Tracker'!J:J,"☑ Pass") | G26: =COUNTIFS('QA Tracker'!C:C,25,'QA Tracker'!I:I,"☑ Pass") | H26: =COUNTIFS('QA Tracker'!C:C,25,'QA Tracker'!L:L,"☑ Yes")
A27: 26 | B27: Trades — Filters, Import, Export, Compare | C27: 3 — Trades | D27: =COUNTIFS('QA Tracker'!C:C,26) | E27: =COUNTIFS('QA Tracker'!C:C,26,'QA Tracker'!F:F,"P0") | F27: =COUNTIFS('QA Tracker'!C:C,26,'QA Tracker'!J:J,"☑ Pass") | G27: =COUNTIFS('QA Tracker'!C:C,26,'QA Tracker'!I:I,"☑ Pass") | H27: =COUNTIFS('QA Tracker'!C:C,26,'QA Tracker'!L:L,"☑ Yes")
A28: 27 | B28: Trades Table — Columns, Sort, Expand | C28: 3 — Trades | D28: =COUNTIFS('QA Tracker'!C:C,27) | E28: =COUNTIFS('QA Tracker'!C:C,27,'QA Tracker'!F:F,"P0") | F28: =COUNTIFS('QA Tracker'!C:C,27,'QA Tracker'!J:J,"☑ Pass") | G28: =COUNTIFS('QA Tracker'!C:C,27,'QA Tracker'!I:I,"☑ Pass") | H28: =COUNTIFS('QA Tracker'!C:C,27,'QA Tracker'!L:L,"☑ Yes")
A29: 28 | B29: Add Trade — Source Picker | C29: 3 — Trades | D29: =COUNTIFS('QA Tracker'!C:C,28) | E29: =COUNTIFS('QA Tracker'!C:C,28,'QA Tracker'!F:F,"P0") | F29: =COUNTIFS('QA Tracker'!C:C,28,'QA Tracker'!J:J,"☑ Pass") | G29: =COUNTIFS('QA Tracker'!C:C,28,'QA Tracker'!I:I,"☑ Pass") | H29: =COUNTIFS('QA Tracker'!C:C,28,'QA Tracker'!L:L,"☑ Yes")
A30: 29 | B30: Add Trade — Trade & Risk (Normal Scenarios) | C30: 3 — Trades | D30: =COUNTIFS('QA Tracker'!C:C,29) | E30: =COUNTIFS('QA Tracker'!C:C,29,'QA Tracker'!F:F,"P0") | F30: =COUNTIFS('QA Tracker'!C:C,29,'QA Tracker'!J:J,"☑ Pass") | G30: =COUNTIFS('QA Tracker'!C:C,29,'QA Tracker'!I:I,"☑ Pass") | H30: =COUNTIFS('QA Tracker'!C:C,29,'QA Tracker'!L:L,"☑ Yes")
A31: 30 | B31: Add Trade — Field Input Extremes | C31: 3 — Trades | D31: =COUNTIFS('QA Tracker'!C:C,30) | E31: =COUNTIFS('QA Tracker'!C:C,30,'QA Tracker'!F:F,"P0") | F31: =COUNTIFS('QA Tracker'!C:C,30,'QA Tracker'!J:J,"☑ Pass") | G31: =COUNTIFS('QA Tracker'!C:C,30,'QA Tracker'!I:I,"☑ Pass") | H31: =COUNTIFS('QA Tracker'!C:C,30,'QA Tracker'!L:L,"☑ Yes")
A32: 31 | B32: Add Trade — Validation Errors | C32: 3 — Trades | D32: =COUNTIFS('QA Tracker'!C:C,31) | E32: =COUNTIFS('QA Tracker'!C:C,31,'QA Tracker'!F:F,"P0") | F32: =COUNTIFS('QA Tracker'!C:C,31,'QA Tracker'!J:J,"☑ Pass") | G32: =COUNTIFS('QA Tracker'!C:C,31,'QA Tracker'!I:I,"☑ Pass") | H32: =COUNTIFS('QA Tracker'!C:C,31,'QA Tracker'!L:L,"☑ Yes")
A33: 32 | B33: Add Trade — Excursion MFE/MAE | C33: 3 — Trades | D33: =COUNTIFS('QA Tracker'!C:C,32) | E33: =COUNTIFS('QA Tracker'!C:C,32,'QA Tracker'!F:F,"P0") | F33: =COUNTIFS('QA Tracker'!C:C,32,'QA Tracker'!J:J,"☑ Pass") | G33: =COUNTIFS('QA Tracker'!C:C,32,'QA Tracker'!I:I,"☑ Pass") | H33: =COUNTIFS('QA Tracker'!C:C,32,'QA Tracker'!L:L,"☑ Yes")
A34: 33 | B34: Add Trade — Tags, Discipline, Notes | C34: 3 — Trades | D34: =COUNTIFS('QA Tracker'!C:C,33) | E34: =COUNTIFS('QA Tracker'!C:C,33,'QA Tracker'!F:F,"P0") | F34: =COUNTIFS('QA Tracker'!C:C,33,'QA Tracker'!J:J,"☑ Pass") | G34: =COUNTIFS('QA Tracker'!C:C,33,'QA Tracker'!I:I,"☑ Pass") | H34: =COUNTIFS('QA Tracker'!C:C,33,'QA Tracker'!L:L,"☑ Yes")
A35: 34 | B35: Add Trade — Persistence & Edit | C35: 3 — Trades | D35: =COUNTIFS('QA Tracker'!C:C,34) | E35: =COUNTIFS('QA Tracker'!C:C,34,'QA Tracker'!F:F,"P0") | F35: =COUNTIFS('QA Tracker'!C:C,34,'QA Tracker'!J:J,"☑ Pass") | G35: =COUNTIFS('QA Tracker'!C:C,34,'QA Tracker'!I:I,"☑ Pass") | H35: =COUNTIFS('QA Tracker'!C:C,34,'QA Tracker'!L:L,"☑ Yes")
A36: 35 | B36: Sources Library — Open & Shell | C36: 4 — Sources | D36: =COUNTIFS('QA Tracker'!C:C,35) | E36: =COUNTIFS('QA Tracker'!C:C,35,'QA Tracker'!F:F,"P0") | F36: =COUNTIFS('QA Tracker'!C:C,35,'QA Tracker'!J:J,"☑ Pass") | G36: =COUNTIFS('QA Tracker'!C:C,35,'QA Tracker'!I:I,"☑ Pass") | H36: =COUNTIFS('QA Tracker'!C:C,35,'QA Tracker'!L:L,"☑ Yes")
A37: 36 | B37: Sources — Tree Navigation | C37: 4 — Sources | D37: =COUNTIFS('QA Tracker'!C:C,36) | E37: =COUNTIFS('QA Tracker'!C:C,36,'QA Tracker'!F:F,"P0") | F37: =COUNTIFS('QA Tracker'!C:C,36,'QA Tracker'!J:J,"☑ Pass") | G37: =COUNTIFS('QA Tracker'!C:C,36,'QA Tracker'!I:I,"☑ Pass") | H37: =COUNTIFS('QA Tracker'!C:C,36,'QA Tracker'!L:L,"☑ Yes")
A38: 37 | B38: Sources — Filter Matrix (Backtests) | C38: 4 — Sources | D38: =COUNTIFS('QA Tracker'!C:C,37) | E38: =COUNTIFS('QA Tracker'!C:C,37,'QA Tracker'!F:F,"P0") | F38: =COUNTIFS('QA Tracker'!C:C,37,'QA Tracker'!J:J,"☑ Pass") | G38: =COUNTIFS('QA Tracker'!C:C,37,'QA Tracker'!I:I,"☑ Pass") | H38: =COUNTIFS('QA Tracker'!C:C,37,'QA Tracker'!L:L,"☑ Yes")
A39: 38 | B39: Sources — Selection & Footer | C39: 4 — Sources | D39: =COUNTIFS('QA Tracker'!C:C,38) | E39: =COUNTIFS('QA Tracker'!C:C,38,'QA Tracker'!F:F,"P0") | F39: =COUNTIFS('QA Tracker'!C:C,38,'QA Tracker'!J:J,"☑ Pass") | G39: =COUNTIFS('QA Tracker'!C:C,38,'QA Tracker'!I:I,"☑ Pass") | H39: =COUNTIFS('QA Tracker'!C:C,38,'QA Tracker'!L:L,"☑ Yes")
A40: 39 | B40: Sources — Go Behavior & Banner | C40: 4 — Sources | D40: =COUNTIFS('QA Tracker'!C:C,39) | E40: =COUNTIFS('QA Tracker'!C:C,39,'QA Tracker'!F:F,"P0") | F40: =COUNTIFS('QA Tracker'!C:C,39,'QA Tracker'!J:J,"☑ Pass") | G40: =COUNTIFS('QA Tracker'!C:C,39,'QA Tracker'!I:I,"☑ Pass") | H40: =COUNTIFS('QA Tracker'!C:C,39,'QA Tracker'!L:L,"☑ Yes")
...

Sheet Test Matrix Reference
A1: Built-in limits & validation reference (from codebase)
A3: STRATEGY BUILDER
A4: Strategy name | B4: Required, max 80 chars
A5: Description | B5: Optional, max 500 chars
A6: Tags | B6: Max 10
A7: Markets | B7: Required, at least 1 (Forex/Futures/Crypto/Stocks)
A8: Instruments | B8: Max 10
A9: Timeframes | B9: Required, max 6; custom TF supported
A10: Cover images | B10: Max 6
A11: Condition title | B11: ~70 chars max
A13: SESSION MODAL
A14: Session name | B14: Required
A15: Primary tickers | B15: Required, max = plan (default 5)
A16: Supporting tickers | B16: Max = plan supporting cap
A17: Start/end dates | B17: Required for range mode
A18: Capital | B18: Required, > 0
A19: Prop firm | B19: Disabled for Futures asset class tab
A21: ADD TRADE VALIDATION
A22: Stop loss | B22: Required, > 0; below entries (long) / above (short)
A23: Targets | B23: Above entries (long) / below (short)
A24: Exit size | B24: Cannot exceed entry size
A25: Excursion | B25: High > low; entry inside range; max ~500R
A26: Extended excursion | B26: Requires closed trade + post range + integer window > 0
A27: Journal trade | B27: Strategy/setup required (non-live journal)
A29: SOURCES
A30: Filter combos | B30: Mode (Std/Prop) × Status (All/Not Started/Active/Completed)
A31: Strategy selection | B31: Partial child checkboxes supported

Sheet S1 Strategies
A1: Step # | B1: Section | C1: Phase | D1: Phase Name | E1: Category | F1: Priority | G1: What to Do | H1: Test Input | I1: Expected Result | J1: Tester A | K1: Tester B | L1: Issue? | M1: Comments
A2: 1 | B2: 1 — Strategies | C2: 1 | D2: Strategy Bank — Access & Shell | E2: Structure | F2: P0 | G2: Open /dashboard/ while logged in. | H2: — | I2: Dashboard shell loads; left nav visible. | J2: — Not tested | K2: — Not tested | L2: — Not tested
A3: 2 | B3: 1 — Strategies | C3: 1 | D3: Strategy Bank — Access & Shell | E3: Structure | F3: P0 | G3: Navigate to Strategies via left nav. | H3: — | I3: Strategy Bank page; header title visible. | J3: — Not tested | K3: — Not tested | L3: — Not tested
A4: 3 | B4: 1 — Strategies | C4: 1 | D4: Strategy Bank — Access & Shell | E4: Structure | F4: P1 | G4: Refresh browser on Strategy Bank. | H4: — | I4: Page reloads; strategies list persists. | J4: — Not tested | K4: — Not tested | L4: — Not tested
A5: 4 | B5: 1 — Strategies | C5: 1 | D5: Strategy Bank — Access & Shell | E5: Structure | F5: P1 | G5: Resize browser: 1920px, 1366px, 1024px widths. | H5: 3 widths | I5: Layout does not overlap or clip header/controls. | J5: — Not tested | K5: — Not tested | L5: — Not tested
A6: 5 | B6: 1 — Strategies | C6: 1 | D6: Strategy Bank — Access & Shell | E6: Structure | F6: P2 | G6: Zoom browser 90% and 110%. | H6: — | I6: Cards/rows remain readable; no broken dropdowns. | J6: — Not tested | K6: — Not tested | L6: — Not tested
A7: 6 | B7: 1 — Strategies | C7: 2 | D7: Strategy Bank — Controls & Empty States | E7: Normal | F7: P0 | G7: Click Build Strategy. | H7: — | I7: Template picker OR builder opens. | J7: — Not tested | K7: — Not tested | L7: — Not tested
A8: 7 | B8: 1 — Strategies | C8: 2 | D8: Strategy Bank — Controls & Empty States | E8: Normal | F8: P1 | G8: Toggle Cards view. | H8: — | I8: Grid of cards with consistent height. | J8: — Not tested | K8: — Not tested | L8: — Not tested
A9: 8 | B9: 1 — Strategies | C9: 2 | D9: Strategy Bank — Controls & Empty States | E9: Normal | F9: P1 | G9: Toggle Rows view. | H9: — | I9: Table rows align; columns readable. | J9: — Not tested | K9: — Not tested | L9: — Not tested
A10: 9 | B10: 1 — Strategies | C10: 2 | D10: Strategy Bank — Controls & Empty States | E10: Normal | F10: P1 | G10: Search partial strategy name. | H10: e.g. 'mom' | I10: Only matching strategies shown. | J10: — Not tested | K10: — Not tested | L10: — Not tested
A11: 10 | B11: 1 — Strategies | C11: 2 | D11: Strategy Bank — Controls & Empty States | E11: Normal | F11: P1 | G11: Search by tag text. | H11: e.g. 'Scalping' | I11: Strategies with that tag appear. | J11: — Not tested | K11: — Not tested | L11: — Not tested
A12: 11 | B12: 1 — Strategies | C12: 2 | D12: Strategy Bank — Controls & Empty States | E12: Normal | F12: P1 | G12: Search gibberish. | H12: zzzznotfound | I12: Empty/no-match message; no crash. | J12: — Not tested | K12: — Not tested | L12: — Not tested
A13: 12 | B13: 1 — Strategies | C13: 2 | D13: Strategy Bank — Controls & Empty States | E13: Normal | F13: P2 | G13: Clear search with ×. | H13: — | I13: Full list restored. | J13: — Not tested | K13: — Not tested | L13: — Not tested
... A45: 44 | B45: 1 — Strategies | C45: 5 | D45: Strategy Builder — Wizard Shell | E45: Logic | F45: P0 | G45: Back from Step 3 → Step 2 → data preserved. | H45: — | I45: No data loss. | J45: — Not tested | K45: — Not tested | L45: — Not tested
A46: 45 | B46: 1 — Strategies | C46: 6 | D46: Builder Step 1 — Strategy Name | E46: Input matrix | F46: P0 | G46: Leave name empty → Next. | I46: Blocked; red border on name field. | J46: — Not tested | K46: — Not tested | L46: — Not tested
A47: 46 | B47: 1 — Strategies | C47: 6 | D47: Builder Step 1 — Strategy Name | E47: Input matrix | F47: P1 | G47: Name = 1 character. | H47: A | I47: Accepts; can proceed if markets+TF set. | J47: — Not tested | K47: — Not tested | L47: — Not tested
A48: 47 | B48: 1 — Strategies | C48: 6 | D48: Builder Step 1 — Strategy Name | E48: Input matrix | F48: P1 | G48: Name = 80 characters (max). | H48: 80×A | I48: Accepts; no truncate in input. | J48: — Not tested | K48: — Not tested | L48: — Not tested
A49: 48 | B49: 1 — Strategies | C49: 6 | D49: Builder Step 1 — Strategy Name | E49: Input matrix | F49: P1 | G49: Name = 81+ characters. | H49: 81×A | I49: Input stops at 80 (maxLength). | J49: — Not tested | K49: — Not tested | L49: — Not tested
A50: 49 | B50: 1 — Strategies | C50: 6 | D50: Builder Step 1 — Strategy Name | E50: Input matrix | F50: P0 | G50: Name = only spaces. | I50: Treated as empty; blocked. | J50: — Not tested | K50: — Not tested | L50: — Not tested
A51: 50 | B51: 1 — Strategies | C51: 6 | D51: Builder Step 1 — Strategy Name | E51: Input matrix | F51: P2 | G51: Name with emoji inline. | H51: Rocket 🚀 Scalp | I51: Displays correctly on card. | J51: — Not tested | K51: — Not tested | L51: — Not tested
A52: 51 | B52: 1 — Strategies | C52: 6 | D52: Builder Step 1 — Strategy Name | E52: Input matrix | F52: P0 | G52: Name special chars. | H52: Test <>&"' | I52: Displays literally; no HTML injection. | J52: — Not tested | K52: — Not tested | L52: — Not tested
A53: 52 | B53: 1 — Strategies | C53: 6 | D53: Builder Step 1 — Strategy Name | E53: Input matrix | F53: P2 | G53: Name Arabic. | H53: استراتيجية الذهب | I53: RTL displays correctly. | J53: — Not tested | K53: — Not tested | L53: — Not tested
A54: 53 | B54: 1 — Strategies | C54: 6 | D54: Builder Step 1 — Strategy Name | E54: Input matrix | F54: P2 | G54: Name duplicate of existing. | H54: same as another | I54: Allowed (duplicates OK) or warn — note behavior. | J54: — Not tested | K54: — Not tested | L54: — Not tested
A55: 54 | B55: 1 — Strategies | C55: 6 | D55: Builder Step 1 — Description & Emoji | E55: Input matrix | F55: P1 | G55: Description empty. | H55: — | I55: Allowed; optional field. | J55: — Not tested | K55: — Not tested | L55: — Not tested
A56: 55 | B56: 1 — Strategies | C56: 6 | D56: Builder Step 1 — Description & Emoji | E56: Input matrix | F56: P1 | G56: Description 500 chars (max). | H56: 500 chars | I56: Counter shows 500/500; accepts. | J56: — Not tested | K56: — Not tested | L56: — Not tested
A57: 56 | B57: 1 — Strategies | C57: 6 | D57: Builder Step 1 — Description & Emoji | E57: Input matrix | F57: P1 | G57: Description 501+ chars. | H57: paste 501 | I57: Blocked at 500 maxLength. | J57: — Not tested | K57: — Not tested | L57: — Not tested
A58: 57 | B58: 1 — Strategies | C58: 6 | D58: Builder Step 1 — Description & Emoji | E58: Input matrix | F58: P2 | G58: Description with newlines. | H58: line1\nline2 | I58: Multiline displays on card/review. | J58: — Not tested | K58: — Not tested | L58: — Not tested
A59: 58 | B59: 1 — Strategies | C59: 6 | D59: Builder Step 1 — Description & Emoji | E59: Input matrix | F59: P1 | G59: Open emoji picker → browse Finance category. | H59: — | I59: Emoji grid loads. | J59: — Not tested | K59: — Not tested | L59: — Not tested
A60: 59 | B60: 1 — Strategies | C60: 6 | D60: Builder Step 1 — Description & Emoji | E60: Input matrix | F60: P2 | G60: Search emoji picker. | H60: chart | I60: Filters emoji list. | J60: — Not tested | K60: — Not tested | L60: — Not tested
A61: 60 | B61: 1 — Strategies | C61: 6 | D61: Builder Step 1 — Description & Emoji | E61: Input matrix | F61: P1 | G61: Select emoji → appears on button. | H61: 📈 | I61: Emoji shows on picker button. | J61: — Not tested | K61: — Not tested | L61: — Not tested
A62: 61 | B62: 1 — Strategies | C62: 6 | D62: Builder Step 1 — Description & Emoji | E62: Input matrix | F62: P2 | G62: Remove emoji via × on button. | H62: — | I62: Emoji clears. | J62: — Not tested | K62: — Not tested | L62: — Not tested
... A156: 527 | B156: 1 — Strategies | C156: 52 | D156: Strategy Bank — Community Tab (disabled) | E156: Edge | F156: P2 | G156: If Community enabled in future build: sort by Win Rate, Name, P&L. | H156: — | I156: Skip if disabled; note N/A. | J156: — Not tested | K156: — Not tested | L156: — Not tested

Sheet S2 Sessions
A1: Step # | B1: Section | C1: Phase | D1: Phase Name | E1: Category | F1: Priority | G1: What to Do | H1: Test Input | I1: Expected Result | J1: Tester A | K1: Tester B | L1: Issue? | M1: Comments
A2: 140 | B2: 2 — Sessions | C2: 14 | D2: Sessions Page — Shell & Stats | E2: Structure | F2: P0 | G2: Open Backtest via left nav. | H2: — | I2: Backtesting Sessions page. | J2: — Not tested | K2: — Not tested | L2: — Not tested
A3: 141 | B3: 2 — Sessions | C3: 14 | D3: Sessions Page — Shell & Stats | E3: Structure | F3: P1 | G3: Verify stats tile: Sessions & Mode (Std/Prop/Journal). | H3: — | I3: Counts match list. | J3: — Not tested | K3: — Not tested | L3: — Not tested
A4: 142 | B4: 2 — Sessions | C4: 14 | D4: Sessions Page — Shell & Stats | E4: Structure | F4: P1 | G4: Hover Total Trades chart bar. | H4: — | I4: Tooltip with session details. | J4: — Not tested | K4: — Not tested | L4: — Not tested
A5: 143 | B5: 2 — Sessions | C5: 14 | D5: Sessions Page — Shell & Stats | E5: Structure | F5: P2 | G5: Profitable Sessions % arc. | H5: — | I5: Percentage displayed. | J5: — Not tested | K5: — Not tested | L5: — Not tested
A6: 144 | B6: 2 — Sessions | C6: 14 | D6: Sessions Page — Shell & Stats | E6: Structure | F6: P2 | G6: Days Tested dots/bars. | H6: — | I6: Visual renders. | J6: — Not tested | K6: — Not tested | L6: — Not tested
A7: 145 | B7: 2 — Sessions | C7: 14 | D7: Sessions Page — Shell & Stats | E7: Structure | F7: P2 | G7: Tickers Tested count. | H7: — | I7: Matches unique tickers. | J7: — Not tested | K7: — Not tested | L7: — Not tested
A8: 146 | B8: 2 — Sessions | C8: 15 | D8: Sessions — Filters & Sort | E8: Configuration | F8: P1 | G8: Click filter tab **All**. | H8: All | I8: Only All sessions shown; badge count correct. | J8: — Not tested | K8: — Not tested | L8: — Not tested
A9: 147 | B9: 2 — Sessions | C9: 15 | D9: Sessions — Filters & Sort | E9: Configuration | F9: P1 | G9: Click filter tab **Not Started**. | H9: Not Started | I9: Only Not Started sessions shown; badge count correct. | J9: — Not tested | K9: — Not tested | L9: — Not tested
A10: 148 | B10: 2 — Sessions | C10: 15 | D10: Sessions — Filters & Sort | E10: Configuration | F10: P1 | G10: Click filter tab **Active**. | H10: Active | I10: Only Active sessions shown; badge count correct. | J10: — Not tested | K10: — Not tested | L10: — Not tested
A11: 149 | B11: 2 — Sessions | C11: 15 | D11: Sessions — Filters & Sort | E11: Configuration | F11: P1 | G11: Click filter tab **Completed**. | H11: Completed | I11: Only Completed sessions shown; badge count correct. | J11: — Not tested | K11: — Not tested | L11: — Not tested
A12: 150 | B12: 2 — Sessions | C12: 15 | D12: Sessions — Filters & Sort | E12: Configuration | F12: P1 | G12: Click filter tab **Standard**. | H12: Standard | I12: Only Standard sessions shown; badge count correct. | J12: — Not tested | K12: — Not tested | L12: — Not tested
A13: 151 | B13: 2 — Sessions | C13: 15 | D13: Sessions — Filters & Sort | E13: Configuration | F13: P1 | G13: Click filter tab **Prop Firm**. | H13: Prop Firm | I13: Only Prop Firm sessions shown; badge count correct. | J13: — Not tested | K13: — Not tested | L13: — Not tested
... A44: 182 | B44: 2 — Sessions | C44: 17 | D44: New Session — Kind Picker | E44: Configuration | F44: P2 | G44: Link broker — Coming Soon. | H44: — | I44: Disabled or blocked. | J44: — Not tested | K44: — Not tested | L44: — Not tested
A45: 183 | B45: 2 — Sessions | C45: 18 | D45: Add Session — Session Info Fields | E45: Input matrix | F45: P0 | G45: Session name empty. | I45: Save/Start disabled. | J45: — Not tested | K45: — Not tested | L45: — Not tested
A46: 184 | B46: 2 — Sessions | C46: 18 | D46: Add Session — Session Info Fields | E46: Input matrix | F46: P2 | G46: Session name 1 char. | H46: A | I46: Accepted. | J46: — Not tested | K46: — Not tested | L46: — Not tested
A47: 185 | B47: 2 — Sessions | C47: 18 | D47: Add Session — Session Info Fields | E47: Input matrix | F47: P2 | G47: Session name very long (200+ chars). | H47: long | I47: Truncated or accepted — note limit. | J47: — Not tested | K47: — Not tested | L47: — Not tested
A48: 186 | B48: 2 — Sessions | C48: 18 | D48: Add Session — Session Info Fields | E48: Input matrix | F48: P1 | G48: Session name special chars. | H48: Test & < > | I48: Displays safely. | J48: — Not tested | K48: — Not tested | L48: — Not tested
A49: 187 | B49: 2 — Sessions | C49: 18 | D49: Add Session — Session Info Fields | E49: Input matrix | F49: P1 | G49: Strategy = None. | H49: None | I49: Session saves without linked strategy. | J49: — Not tested | K49: — Not tested | L49: — Not tested
A50: 188 | B50: 2 — Sessions | C50: 18 | D50: Add Session — Session Info Fields | E50: Input matrix | F50: P1 | G50: Strategy = pick each of your strategies. | H50: each | I50: Strategy name links. | J50: — Not tested | K50: — Not tested | L50: — Not tested
A51: 189 | B51: 2 — Sessions | C51: 18 | D51: Add Session — Session Info Fields | E51: Input matrix | F51: P2 | G51: New Strategy shortcut. | H51: — | I51: Navigates to strategy create. | J51: — Not tested | K51: — Not tested | L51: — Not tested
A52: 190 | B52: 2 — Sessions | C52: 18 | D52: Add Session — Session Info Fields | E52: Input matrix | F52: P2 | G52: Description empty vs filled. | H52: paragraph | I52: Saves both cases. | J52: — Not tested | K52: — Not tested | L52: — Not tested
A53: 191 | B53: 2 — Sessions | C53: 19 | D53: Add Session — Asset Class & Symbols | E53: Configuration | F53: P0 | G53: Set asset class **Forex**; open symbol picker. | H53: Forex | I53: Picker shows Forex symbols; can add to session. | J53: — Not tested | K53: — Not tested | L53: — Not tested
A54: 192 | B54: 2 — Sessions | C54: 19 | D54: Add Session — Asset Class & Symbols | E54: Configuration | F54: P0 | G54: Set asset class **Futures**; open symbol picker. | H54: Futures | I54: Picker shows Futures symbols; can add to session. | J54: — Not tested | K54: — Not tested | L54: — Not tested
A55: 193 | B55: 2 — Sessions | C55: 19 | D55: Add Session — Asset Class & Symbols | E55: Configuration | F55: P0 | G55: Set asset class **Stocks**; open symbol picker. | H55: Stocks | I55: Picker shows Stocks symbols; can add to session. | J55: — Not tested | K55: — Not tested | L55: — Not tested
A56: 194 | B56: 2 — Sessions | C56: 19 | D56: Add Session — Asset Class & Symbols | E56: Configuration | F56: P0 | G56: Set asset class **Crypto**; open symbol picker. | H56: Crypto | I56: Picker shows Crypto symbols; can add to session. | J56: — Not tested | K56: — Not tested | L56: — Not tested
A57: 195 | B57: 2 — Sessions | C57: 19 | D57: Add Session — Asset Class & Symbols | E57: Edge | F57: P0 | G57: Add 1 primary ticker. | H57: EURUSD | I57: Chip appears; required met. | J57: — Not tested | K57: — Not tested | L57: — Not tested
... A181: 525 | B181: 2 — Sessions | C181: 51 | D181: Add Session — Toggle Disabled States | E181: Structure | F181: P2 | G181: Trading costs OFF → per-class overrides hidden. | H181: — | I181: Section collapsed. | J181: — Not tested | K181: — Not tested | L181: — Not tested

Sheet S3 Trades
A1: Step # | B1: Section | C1: Phase | D1: Phase Name | E1: Category | F1: Priority | G1: What to Do | H1: Test Input | I1: Expected Result | J1: Tester A | K1: Tester B | L1: Issue? | M1: Comments
A2: 286 | B2: 3 — Trades | C2: 25 | D2: Trades Page — Shell & Header | E2: Structure | F2: P0 | G2: Open Trades via left nav. | H2: — | I2: Trade table visible. | J2: — Not tested | K2: — Not tested | L2: — Not tested
A3: 287 | B3: 3 — Trades | C3: 25 | D3: Trades Page — Shell & Header | E3: Structure | F3: P0 | G3: Source switcher shows active source label. | H3: — | I3: Matches applied source. | J3: — Not tested | K3: — Not tested | L3: — Not tested
A4: 288 | B4: 3 — Trades | C4: 25 | D4: Trades Page — Shell & Header | E4: Structure | F4: P1 | G4: With no source applied, note empty state. | H4: — | I4: Prompt to select source or empty table. | J4: — Not tested | K4: — Not tested | L4: — Not tested
A5: 289 | B5: 3 — Trades | C5: 26 | D5: Trades — Filters, Import, Export, Compare | E5: Configuration | F5: P0 | G5: Open Filters panel. | H5: — | I5: Date, scope, tags, outcome, privacy options. | J5: — Not tested | K5: — Not tested | L5: — Not tested
A6: 290 | B6: 3 — Trades | C6: 26 | D6: Trades — Filters, Import, Export, Compare | E6: Configuration | F6: P1 | G6: Filter date range: last 30 days. | H6: 30d | I6: Table filters. | J6: — Not tested | K6: — Not tested | L6: — Not tested
A7: 291 | B7: 3 — Trades | C7: 26 | D7: Trades — Filters, Import, Export, Compare | E7: Configuration | F7: P2 | G7: Filter date range: custom 1 day. | H7: 1 day | I7: Narrow results. | J7: — Not tested | K7: — Not tested | L7: — Not tested
A8: 292 | B8: 3 — Trades | C8: 26 | D8: Trades — Filters, Import, Export, Compare | E8: Configuration | F8: P1 | G8: Filter by outcome: winners only. | H8: winners | I8: Only positive P&L rows. | J8: — Not tested | K8: — Not tested | L8: — Not tested
A9: 293 | B9: 3 — Trades | C9: 26 | D9: Trades — Filters, Import, Export, Compare | E9: Configuration | F9: P1 | G9: Filter by outcome: losers only. | H9: losers | I9: Only negative P&L. | J9: — Not tested | K9: — Not tested | L9: — Not tested
A10: 294 | B10: 3 — Trades | C10: 26 | D10: Trades — Filters, Import, Export, Compare | E10: Configuration | F10: P2 | G10: Combine 3 filters simultaneously. | H10: multi | I10: Intersection correct. | J10: — Not tested | K10: — Not tested | L10: — Not tested
A11: 295 | B11: 3 — Trades | C11: 26 | D11: Trades — Filters, Import, Export, Compare | E11: Configuration | F11: P1 | G11: Clear all filters. | H11: — | I11: Full list returns. | J11: — Not tested | K11: — Not tested | L11: — Not tested
A12: 296 | B12: 3 — Trades | C12: 26 | D12: Trades — Filters, Import, Export, Compare | E12: Configuration | F12: P0 | G12: Export CSV with trades. | H12: — | I12: File downloads with correct columns. | J12: — Not tested | K12: — Not tested | L12: — Not tested
A13: 297 | B13: 3 — Trades | C13: 26 | D13: Trades — Filters, Import, Export, Compare | E13: Configuration | F13: P2 | G13: Export with zero trades. | H13: — | I13: Disabled or empty file message. | J13: — Not tested | K13: — Not tested | L13: — Not tested
... A133: 533 | B133: 3 — Trades | C133: 53 | D133: Trades — Import/Export File Matrix | E133: Edge | F133: P2 | G133: Import 1000-row CSV. | H133: stress | I133: Completes without browser freeze. | J133: — Not tested | K133: — Not tested | L133: — Not tested

Sheet S4 Sources
A1: Step # | B1: Section | C1: Phase | D1: Phase Name | E1: Category | F1: Priority | G1: What to Do | H1: Test Input | I1: Expected Result | J1: Tester A | K1: Tester B | L1: Issue? | M1: Comments
A2: 386 | B2: 4 — Sources | C2: 35 | D2: Sources Library — Open & Shell | E2: Structure | F2: P0 | G2: Dashboard → click source chip. | H2: — | I2: Library overlay opens. | J2: — Not tested | K2: — Not tested | L2: — Not tested
A3: 387 | B3: 4 — Sources | C3: 35 | D3: Sources Library — Open & Shell | E3: Structure | F3: P0 | G3: Trades → source switcher. | H3: — | I3: Same library UI. | J3: — Not tested | K3: — Not tested | L3: — Not tested
A4: 388 | B4: 4 — Sources | C4: 35 | D4: Sources Library — Open & Shell | E4: Structure | F4: P1 | G4: Verify overlay: tree left, list center, footer. | H4: — | I4: Three-zone layout. | J4: — Not tested | K4: — Not tested | L4: — Not tested
A5: 389 | B5: 4 — Sources | C5: 35 | D5: Sources Library — Open & Shell | E5: Structure | F5: P2 | G5: Click outside overlay. | H5: — | I5: Stays open or closes — note behavior. | J5: — Not tested | K5: — Not tested | L5: — Not tested
A6: 390 | B6: 4 — Sources | C6: 35 | D6: Sources Library — Open & Shell | E6: Structure | F6: P2 | G6: Resize window with library open. | H6: — | I6: Layout adapts. | J6: — Not tested | K6: — Not tested | L6: — Not tested
A7: 391 | B7: 4 — Sources | C7: 36 | D7: Sources — Tree Navigation | E7: Structure | F7: P0 | G7: Expand Backtest Sessions. | H7: — | I7: Standard and Prop Firm children. | J7: — Not tested | K7: — Not tested | L7: — Not tested
A8: 392 | B8: 4 — Sources | C8: 36 | D8: Sources — Tree Navigation | E8: Structure | F8: P0 | G8: Expand Standard under Backtests. | H8: — | I8: Standard sessions listed. | J8: — Not tested | K8: — Not tested | L8: — Not tested
A9: 393 | B9: 4 — Sources | C9: 36 | D9: Sources — Tree Navigation | E9: Structure | F9: P0 | G9: Expand Prop Firm under Backtests. | H9: — | I9: Prop sessions listed. | J9: — Not tested | K9: — Not tested | L9: — Not tested
A10: 394 | B10: 4 — Sources | C10: 36 | D10: Sources — Tree Navigation | E10: Structure | F10: P0 | G10: Expand Live Journals. | H10: — | I10: Personal and Prop children. | J10: — Not tested | K10: — Not tested | L10: — Not tested
A11: 395 | B11: 4 — Sources | C11: 36 | D11: Sources — Tree Navigation | E11: Structure | F11: P1 | G11: Expand Strategies tree node. | H11: — | I11: Strategy groups with children. | J11: — Not tested | K11: — Not tested | L11: — Not tested
A12: 396 | B12: 4 — Sources | C12: 36 | D12: Sources — Tree Navigation | E12: Structure | F12: P2 | G12: Collapse all then re-expand. | H12: — | I12: State consistent. | J12: — Not tested | K12: — Not tested | L12: — Not tested
A13: 397 | B13: 4 — Sources | C13: 37 | D13: Sources — Filter Matrix (Backtests) | E13: Configuration | F13: P2 | G13: Mode **Standard** + Status **All**. | H13: Standard+All | I13: List shows only matching sessions; count in footer updates. | J13: — Not tested | K13: — Not tested | L13: — Not tested
... A75: 541 | B75: 4 — Sources | C75: 55 | D75: Sources — Cancel vs Go State Machine | E75: Logic | F75: P1 | G75: Partial strategy children → Go. | H75: — | I75: Dashboard scoped to partial set. | J75: — Not tested | K75: — Not tested | L75: — Not tested
