Workbook

Sheet Dashboard
B1: TALARIA · DASHBOARD BUILD
B2: Phase Verification — Progress Dashboard
B3: Live roll-up of every phase. Update Status on the phase tabs; this page recalculates automatically.
B6: Phase | C6: Items | D6: Pass | E6: Fail | F6: In Prog. | G6: % Complete | H6: Gates Passed
B7: Cross-Phase Rules | C7: 12 | D7: =COUNTIF('Cross-Phase Rules'!E7:E18,"Pass") -> 0 | E7: =COUNTIF('Cross-Phase Rules'!E7:E18,"Fail") -> 0 | F7: =COUNTIF('Cross-Phase Rules'!E7:E18,"In Progress") -> 0 | G7: =IF(C7=0,0,COUNTIF('Cross-Phase Rules'!E7:E18,"Pass")/C7) -> 0 | H7: =(--('Cross-Phase Rules'!E7="Pass")+--('Cross-Phase Rules'!E8="Pass")+--('Cross-Phase Rules'!E17="Pass"))&" / 3" -> 0 / 3
B8: Phase 1 — MVP | C8: 30 | D8: =COUNTIF('Phase 1 — MVP'!E7:E42,"Pass") -> 0 | E8: =COUNTIF('Phase 1 — MVP'!E7:E42,"Fail") -> 0 | F8: =COUNTIF('Phase 1 — MVP'!E7:E42,"In Progress") -> 0 | G8: =IF(C8=0,0,COUNTIF('Phase 1 — MVP'!E7:E42,"Pass")/C8) -> 0 | H8: =(--('Phase 1 — MVP'!E7="Pass")+--('Phase 1 — MVP'!E8="Pass")+--('Phase 1 — MVP'!E17="Pass")+--('Phase 1 — MVP'!E18="Pass")+--('Phase 1 — MVP'!E19="Pass")+--('Phase 1 — MVP'!E30="Pass")+--('Phase 1 — MVP'!E41="Pass")+--('Phase 1 — MVP'!E42="Pass"))&" / 8" -> 0 / 8
B9: Phase 2 — Analytics | C9: 23 | D9: =COUNTIF('Phase 2 — Analytics'!E7:E37,"Pass") -> 0 | E9: =COUNTIF('Phase 2 — Analytics'!E7:E37,"Fail") -> 0 | F9: =COUNTIF('Phase 2 — Analytics'!E7:E37,"In Progress") -> 0 | G9: =IF(C9=0,0,COUNTIF('Phase 2 — Analytics'!E7:E37,"Pass")/C9) -> 0 | H9: =(--('Phase 2 — Analytics'!E7="Pass")+--('Phase 2 — Analytics'!E9="Pass")+--('Phase 2 — Analytics'!E17="Pass")+--('Phase 2 — Analytics'!E20="Pass")+--('Phase 2 — Analytics'!E24="Pass")+--('Phase 2 — Analytics'!E31="Pass")+--('Phase 2 — Analytics'!E36="Pass")+--('Phase 2 — Analytics'!E37="Pass"))&" / 8" -> 0 / 8
B10: Phase 3 — Finish | C10: 32 | D10: =COUNTIF('Phase 3 — Finish'!E7:E46,"Pass") -> 0 | E10: =COUNTIF('Phase 3 — Finish'!E7:E46,"Fail") -> 0 | F10: =COUNTIF('Phase 3 — Finish'!E7:E46,"In Progress") -> 0 | G10: =IF(C10=0,0,COUNTIF('Phase 3 — Finish'!E7:E46,"Pass")/C10) -> 0 | H10: =(--('Phase 3 — Finish'!E7="Pass")+--('Phase 3 — Finish'!E9="Pass")+--('Phase 3 — Finish'!E13="Pass")+--('Phase 3 — Finish'!E14="Pass")+--('Phase 3 — Finish'!E16="Pass")+--('Phase 3 — Finish'!E17="Pass")+--('Phase 3 — Finish'!E18="Pass")+--('Phase 3 — Finish'!E21="Pass")+--('Phase 3 — Finish'!E22="Pass")+--('Phase 3 — Finish'!E24="Pass")+--('Phase 3 — Finish'!E26="Pass")+--('Phase 3 — Finish'!E27="Pass")+--('Phase 3 — Finish'!E37="Pass")+--('Phase 3 — Finish'!E38="Pass")+--('Phase 3 — Finish'!E39="Pass")+--('Phase 3 — Finish'!E42="Pass")+--('Phase 3 — Finish'!E43="Pass")+--('Phase 3 — Finish'!E44="Pass")+--('Phase 3 — Finish'!E45="Pass")+--('Phase 3 — Finish'!E46="Pass"))&" / 20" -> 0 / 20
B11: TOTAL | C11: =SUM(C7:C10) -> 97 | D11: =SUM(D7:D10) -> 0 | E11: =SUM(E7:E10) -> 0 | F11: =SUM(F7:F10) -> 0 | G11: =IF(C11=0,0,D11/C11) -> 0
B14: OVERALL COMPLETE | D14: =G11 -> 0
B16: ⚠ A phase is only DONE when every GATE item on its tab shows Pass. Gates are hard blockers — do not start the next phase until all gates pass.
B18: STATUS LEGEND
B19: Pass | C19: Fail | D19: In Progress | E19: Not Started | F19: N/A

Sheet Cross-Phase Rules
B1: TALARIA · DASHBOARD BUILD
B2: Cross-Phase Rules
B3: Verify these in every phase — applies to Phase 1, 2 and 3
B5: ID | C5: GATE | D5: Checklist item | E5: Status | F5: Verified by | G5: Date | H5: Notes
B6: CROSS-PHASE RULES — verify in EVERY phase
B7: X-01 | C7: GATE | D7: No Basic/Advanced toggle exists anywhere — single categorized navigation only. | E7: Not Started
B8: X-02 | C8: GATE | D8: Zero console errors on any navigation path. | E8: Not Started
B9: X-03 | D9: Design tokens only — no hardcoded colors. Sharp corners (radius 0). No card drop-shadows. | E9: Not Started
B10: X-04 | D10: Typography uses only the scale: 8 / 10 / 14 / 16 / 24 px. Section labels 8px weight 800 uppercase. | E10: Not Started
B11: X-05 | D11: Tabular-nums on every number. Numbers right-aligned, labels start-aligned. | E11: Not Started
B12: X-06 | D12: View-Mode (Dollars / % / R / Pips / Ticks / Privacy) correct on every monetary display in scope. | E12: Not Started
B13: X-07 | D13: RTL: layout mirrors; charts and digits do NOT mirror. | E13: Not Started
B14: X-08 | D14: Filter change re-renders visible components within 200ms at 5,000 trades (worker jobs show progress). | E14: Not Started
B15: X-09 | D15: Missing-field stubs degrade gracefully ('data not available'), each flagged // TODO: engine must populate. | E15: Not Started
B16: X-10 | D16: Hash routes bookmarkable; restore source + filter + component state. | E16: Not Started
B17: X-11 | C17: GATE | D17: Four modes behave per spec: Standard (opt-in prop toolkit), Prop (challenge configurator + variation optimizer + simulation), Live (private/prop + discipline + Demon Catcher), Strategy (merged + reconciliation). | E17: Not Started
B18: X-12 | D18: Risk-adjusted metrics (Sharpe/Sortino/Calmar/CAGR/Kelly/SQN/Recovery/Ulcer) all sourced from metrics.ts; surfaced in Quant KPI Strip / Consistency / Rolling. | E18: Not Started

Sheet Phase 1 — MVP
B1: TALARIA · DASHBOARD BUILD
B2: Phase 1 — MVP
B3: Shell · Primitives · Data layer + metrics.ts · ESSENTIALS (19) · EXCURSION (16)
B5: ID | C5: GATE | D5: Checklist item | E5: Status | F5: Verified by | G5: Date | H5: Notes
B6: SHELL & INFRASTRUCTURE
B7: 1-01 | C7: GATE | D7: Top bar present: logo, source selector, session selector, filter pills, View-Mode dropdown, breadcrumb. Compare + Export buttons present but disabled. | E7: Not Started
B8: 1-02 | C8: GATE | D8: Side-nav shows ALL EIGHT categories; ESSENTIALS + EXCURSION active, other six greyed with 'coming soon'. | E8: Not Started
B9: 1-03 | D9: Source selector switches Standard / Live / Strategy fully; Prop Firm selectable and ESSENTIALS/EXCURSION still render for it. | E9: Not Started
B10: 1-04 | D10: Active item styling: 3px left accent, dim-blue bg, label in accent. Breadcrumb updates. | E10: Not Started
B11: 1-05 | D11: Last-viewed component persists to localStorage; defaults to Talaria Score on first open. | E11: Not Started
B12: 1-06 | D12: Navigation is a content swap (no reload); all state persists across navigation. | E12: Not Started
B13: PRIMITIVES (built + tested in isolation)
B14: 1-07 | D14: GaugeRing, Sparkline, DotTrail, StackedRatioBar, ProgressBar, BoxPlotMini, HeatmapCell, KpiCard, ChartFrame, SubWindow. | E14: Not Started
B15: 1-08 | D15: SubWindow: draggable, resizable, header (title+pin+close), footer (Export PNG/CSV/JSON + Copy + Close), Escape + click-outside close, one at a time, 150ms fade+scale. | E15: Not Started
B16: DATA LAYER
B17: 1-09 | C17: GATE | D17: Trade + Session contracts implemented exactly as specified. | E17: Not Started
B18: 1-10 | C18: GATE | D18: talariaScore() deterministic and matches formula (0.30 profit + 0.30 risk + 0.20 consistency + 0.20 discipline); cached on session. | E18: Not Started
B19: 1-10b | C19: GATE | D19: metrics.ts risk-adjusted library built (Sharpe, Sortino, Calmar, CAGR, Kelly %, SQN, Recovery Factor, Ulcer Index); single source of truth, no ad-hoc recomputation. | E19: Not Started
B20: 1-10c | D20: Quant KPI Strip renders all 8 risk-adjusted metrics from metrics.ts with sparklines + healthy/marginal/poor bands. | E20: Not Started
B21: 1-11 | D21: subScores(), dayWinRate(), drawdownStats(), and standard aggregations built + memoized. | E21: Not Started
B22: ESSENTIALS (17) — each renders without error
B23: 1-12 | D23: Talaria Score · Sub-Score Breakdown · Strategy Radar · KPI Strip · Quant KPI Strip · Equity Curve · Cumulative R Curve · Drawdown · Win/Loss Distribution. | E23: Not Started
B24: 1-13 | D24: Balance Waterfall · Performance Calendar · Daily P&L Heatmap · Performance by Instrument/Session/Day · Instrument Bubble · Streaks & Records · Consistency · Trade Journal · Best & Worst Trades · Performance Highlights. | E24: Not Started
B25: 1-14 | D25: Equity Curve tabs work (Equity / Cum P&L / Returns / Rolling 30 / vs Buy&Hold / vs Random); brush zoom; annotations. | E25: Not Started
B26: 1-15 | D26: Trade Journal rows show mini equity sparkline + rule-adherence dot; row hover highlights equity curve. | E26: Not Started
B27: EXCURSION (15) — each renders without error
B28: 1-16 | D28: Session Stat Cards (7) · Excursion Stat Cards (7) · What-If Bars · Capture Ratio Histogram · Post-Exit MFE Curve · Post-Exit MFE by Setup. | E28: Not Started
B29: 1-17 | D29: MAE Distribution · MFE Distribution · During vs Total MFE Scatter · MAE vs MFE Scatter · Trade Path Cloud · Box Plots · Setup Comparison · Losers Recovery Rate · Per-Instrument Breakdown Table · Trade Duration Analysis. | E29: Not Started
B30: 1-18 | C30: GATE | D30: Excursion components correctly read barCloseR[] / barHighR[] / barLowR[]. | E30: Not Started
B31: 1-19 | D31: Gross/Net toggle and Session-Warning include/exclude filters work. | E31: Not Started
B32: LEARNINGS FROM LAST YEAR'S BUILD (v1)
B33: 1-L1 | D33: Persistent Current Balance pill in the top bar (respects Privacy mode); Live freshness indicator hook present. | E33: Not Started
B34: 1-L2 | D34: Equity Curve granularity selector (Daily/Weekly/Monthly/Quarterly/Yearly) + chart-type (Area/Line) + accumulation (Cumulative/Per-period) toggles. | E34: Not Started
B35: 1-L3 | D35: Daily P&L Heatmap has a weekly-total column on the right of the grid. | E35: Not Started
B36: 1-L4 | D36: Talaria Score shows a tier sublabel (Developing / Proficient / Strong / Elite); no separate star rating. | E36: Not Started
B37: 1-L5 | D37: Trade Journal rows show inline note icon + screenshot-count badge. | E37: Not Started
B38: 1-L6 | D38: Performance Highlights strip on the landing view (Best Setup / Instrument / Time / Day), detection shared with Edge Finder. | E38: Not Started
B39: 1-L7 | D39: Trade Duration Analysis built as three linked bucket charts (P&L / count / win rate) with median + average reference lines. | E39: Not Started
B40: PHASE 1 SIGN-OFF
B41: 1-20 | C41: GATE | D41: All 34 components render on sample data; all cross-phase rules pass. | E41: Not Started
...

Sheet Phase 2 — Analytics
B1: TALARIA · DASHBOARD BUILD
B2: Phase 2 — Analytical Depth
B3: What-If Simulator · Statistical · Patterns & Behavior · Strategy Health (22 components)
B5: ID | C5: GATE | D5: Checklist item | E5: Status | F5: Verified by | G5: Date | H5: Notes
B6: REGRESSION GUARD
B7: 2-01 | C7: GATE | D7: Nothing from Phase 1 changed, restyled, or regressed. All 32 Phase-1 components still pass. | E7: Not Started
B8: WORKER INFRASTRUCTURE
B9: 2-02 | C9: GATE | D9: Web Worker harness built; jobs run off the main thread; UI stays responsive. | E9: Not Started
B10: 2-03 | D10: Jobs present: monteCarlo, coinFlip, tpslReplay, edgeFinder, behavioralScan, sequenceReorder, variableCombos. | E10: Not Started
B11: 2-04 | D11: In-flight jobs cancel on filter change; awaiting components show a 'computing…' state. | E11: Not Started
B12: NEW COMPUTED METRICS (memoized, tested)
B13: 2-05 | D13: expectancyByTpSl, rollingMetric, autocorrelation, runsTest, correlationMatrix, tagCross, tagPerformance. | E13: Not Started
B14: 2-06 | D14: edgeFinderInsights, behavioralTags, tiltSeries, regimeStats, edgeDecay, optimalF, sequenceRisk. | E14: Not Started
B15: WHAT-IF SIMULATOR (5)
B16: 2-07 | D16: Expectancy Heatmap · Simulated vs Actual Equity · TP/SL Optimizer · Planned vs Actual Discipline · Advanced Management Stats. | E16: Not Started
B17: 2-08 | C17: GATE | D17: TP/SL Optimizer + Expectancy Heatmap replay barHighR[]/barLowR[] with SL checked BEFORE TP; flipped trades flash; live stats update. | E17: Not Started
B18: STATISTICAL (6)
B19: 2-09 | D19: R-Multiple Distribution · Rolling Metrics · Monte Carlo & Pass Probability · Autocorrelation · Symbol Correlation Matrix · Win/Loss Runs Test. | E19: Not Started
B20: 2-10 | C20: GATE | D20: Monte Carlo + Coin Flip complete under 5s; vs-Random shows confidence score + p-value. | E20: Not Started
B21: 2-11 | D21: Monte Carlo Prop-Firm tab shows clean 'Prop Firm source required' placeholder when source ≠ Prop Firm. | E21: Not Started
B22: PATTERNS & BEHAVIOR (8)
B23: 2-12 | D23: Tag Cross-Analysis Matrix · Variables Analysis · Variables Ranking Table · Tag Performance Tables · Trade Flow (Sankey) · Edge Finder · Behavioral Tilt Timeline · Execution & Rule Adherence · Price Behavior Explorer · Market Regime Matrix. | E23: Not Started
B24: 2-13 | C24: GATE | D24: Tag Cross-Analysis Matrix intersects pre × post tags, confidence-shades <5-trade cells, click-to-drill works. | E24: Not Started
B25: 2-14 | D25: Rule Adherence compares with-rules vs without-rules using rulesFollowed/rulesViolated. | E25: Not Started
B26: 2-15 | D26: Edge Finder surfaces plausible patterns; Behavioral flags ≥2 patterns on a trigger session. | E26: Not Started
B27: STRATEGY HEALTH (3)
B28: 2-16 | D28: Edge Decay · Position Sizing (Optimal F) · Sequence Risk. | E28: Not Started
B29: 2-17 | D29: Sequence Risk reorder distribution runs in a worker; actual max-DD line shown. | E29: Not Started
B30: LEARNINGS FROM LAST YEAR'S BUILD (v1)
B31: 2-L1 | C31: GATE | D31: Variables Analysis: N-way tag-combination explorer (Single/Pairs/Triples), min-trades filter, top/bottom combos, win-rate-vs-P&L bubble scatter. Worker-backed. | E31: Not Started
B32: 2-L2 | D32: Variables Ranking Table: flat sortable per-variable stats (Trades/Win%/Avg R/P&L/PF/Max DD/Expectancy); negative-P&L flagged red. | E32: Not Started
B33: 2-L3 | D33: SQN (System Quality Number) computed and surfaced in Rolling Metrics + as a Quant KPI option. | E33: Not Started
B34: 2-L4 | D34: Trade Duration (Phase 1) upgraded to / confirmed as three-linked-bucket-chart layout. | E34: Not Started
B35: PHASE 2 SIGN-OFF
B36: 2-18 | C36: GATE | D36: Four categories un-greyed; all 24 Phase-2 components render on Standard/Live/Strategy. | E36: Not Started
B37: 2-19 | C37: GATE | D37: PROP CHALLENGE, LIVE DISCIPLINE, STRATEGY SOURCE and EXPORT still greyed. | E37: Not Started

Sheet Phase 3 — Finish
B1: TALARIA · DASHBOARD BUILD
B2: Phase 3 — Prop Firm, Export & Finish
B3: Prop Firm views · Export · Compare mode · Mentor links · Final polish
B5: ID | C5: GATE | D5: Checklist item | E5: Status | F5: Verified by | G5: Date | H5: Notes
B6: REGRESSION GUARD
B7: 3-01 | C7: GATE | D7: Nothing from Phases 1-2 changed or regressed. All Phase 1-2 components still pass. | E7: Not Started
B8: MODE / SOURCE WIRING
B9: 3-02 | C9: GATE | D9: Contracts populated: propChallenge (1-step/2-step, futures/forex, per-phase rules, drawdownType static/trailing/EOD), accountType, planAdherence/hypotheticalRr/demons, disciplineScore/demonLog, mergedSources. | E9: Not Started
B10: 3-03 | D10: New /utils built: dailyRuleUtilization, passProbability, ruleSensitivity, dailyLimitOptimize, variationOptimize, disciplineScore, planAdherenceEquity, reconcile, sourceAttribution. | E10: Not Started
B11: 3-04 | D11: Dormant overlays activated: Daily P&L Heatmap near-breach borders; Monte Carlo rule lines + Pass Probability gauge + preset comparison. | E11: Not Started
B12: PROP CHALLENGE CATEGORY (5) — prop-aware gating
B13: 3-05 | C13: GATE | D13: Gating correct: shown by default in Prop mode; opt-in in Standard/Strategy (after configuring a challenge); auto-on for Live prop accounts. | E13: Not Started
B14: 3-05b | C14: GATE | D14: Challenge Configurator: asset class (futures/forex), structure (1-step/2-step/instant), firm presets, per-phase rules with drawdown type; writes propChallenge and gates the rest. | E14: Not Started
B15: 3-06 | D15: Rule Compliance & Utilization: phase-aware; correctly tracks static vs trailing vs EOD-trailing drawdown; near-miss days flagged. | E15: Not Started
B16: 3-07 | C16: GATE | D16: Pass Probability & Simulation: gauge + failure-cause + preset comparison (FTMO/MyForexFunds/The5ers/FundedNext/Topstep/Apex) + combined 2-step probability; < 5s. | E16: Not Started
B17: 3-07b | C17: GATE | D17: Variation Optimizer: sweeps STRATEGY variations AND CHALLENGE variations, ranks by pass probability, stars cells above threshold; worker-backed with grid caps. | E17: Not Started
B18: 3-08 | C18: GATE | D18: Daily Limit Optimization: dual sliders, day-by-day re-simulation, Original vs Optimized (Improvement % / Days Saved / Risk Reduction %); lighter Standard variant works. | E18: Not Started
B19: 3-08c | D19: Whole category renders on a failing-evaluation session without error. | E19: Not Started
B20: LIVE DISCIPLINE CATEGORY (3) — Live only
B21: 3-LD1 | C21: GATE | D21: Category visible ONLY when source = Live. Untagged live trades enforced to be classified (According to plan / Out of plan / Missed trade). | E21: Not Started
B22: 3-LD2 | C22: GATE | D22: Discipline Filter & Score: adherence donut + Discipline Score 0-100 (missed-trade weighted by hypotheticalRr) + score trend. | E22: Not Started
B23: 3-LD3 | D23: Plan-Adherence Equity: Actual vs Strategy curves with deviation-cost gap in $ and R; missed/out-of-plan cost cards. | E23: Not Started
B24: 3-LD4 | C24: GATE | D24: Demon Catcher renders the ARENA UI (cards sized by frequency, boss-to-slay spotlight, fade/slain state, 8-in-a-row warning, Survival→Growth→Consistency→Profitability rail) — NOT a spreadsheet. | E24: Not Started
B25: STRATEGY SOURCE CATEGORY (2) — Strategy only
B26: 3-SS1 | C26: GATE | D26: Category visible ONLY when source = Strategy. Source Reconciliation: tag-mapping, instrument-mapping, date-range mode (union/intersection/custom), scale normalization (R/%/none), currency, conflict panel. | E26: Not Started
B27: 3-SS2 | C27: GATE | D27: Cross-source views degrade gracefully (banners, hidden sub-visuals) until conflicts resolved — never show wrong numbers. | E27: Not Started
B28: 3-SS3 | D28: Source Attribution Breakdown: decompose aggregate by originSource + backtest-vs-live divergence + per-source KPI cards. | E28: Not Started
B29: EXPORT CATEGORY (2)
B30: 3-09 | D30: Report Builder: templates, page + card selectors, cover options, format toggle (PDF/HTML/gallery), live preview, generate. Output respects View Mode + filters. | E30: Not Started
B31: 3-10 | D31: Comparison View: two sessions, overlaid equity curves, delta column, diff heatmaps, common-vs-unique trades, significance p-value. | E31: Not Started
B32: CROSS-CUTTING
B33: 3-11 | D33: Compare mode: top-bar button enabled; inline comparison works from supporting components. | E33: Not Started
B34: 3-12 | D34: Mentor share links: encode source + session + component + filters + readonly; restore exact view (backend stubbed + flagged if needed). | E34: Not Started
B35: 3-L1 | D35: Live freshness indicator wired to actual Live sync state ('Updated Xs ago' / 'Live'). (v1 'auto-updating every 30s'.) | E35: Not Started
B36: FINAL POLISH
B37: 3-13 | C37: GATE | D37: Accessibility: nav landmark, aria-labels, keyboard nav (Tab/Enter/Arrows), visible focus, screen-reader announcement of active component. | E37: Not Started
B38: 3-14 | C38: GATE | D38: RTL audit across all ten categories passes. | E38: Not Started
B39: 3-15 | C39: GATE | D39: Performance: 200ms filter budget at 5,000 trades; all simulations in workers with progress + cancel; 60fps on scroll/filter. | E39: Not Started
B40: 3-16 | D40: View-Mode audit across every component. Empty/error states verified everywhere. | E40: Not Started
B41: WHOLE-DASHBOARD DEFINITION OF DONE
...

Sheet How to Use
B1: TALARIA · DASHBOARD BUILD
B2: How to use this checklist
B5: 1. Work through the phase tabs in order: Phase 1 → Phase 2 → Phase 3.
B6: 2. For each row, set the Status dropdown (column E) to Not Started / In Progress / Pass / Fail / N/A.
B7: The cell colors automatically: green Pass, red Fail, gold In Progress.
B8: 3. Fill in 'Verified by' and 'Date' when an item is checked, and use 'Notes' for anything that needs follow-up.
B9: 4. Rows marked GATE (red) are hard blockers. A phase is NOT done until every GATE row on its tab is Pass.
B10: 5. The Cross-Phase Rules tab applies to every phase — re-verify it at the end of Phase 1, 2 and 3.
B11: 6. The Dashboard tab rolls everything up automatically: pass/fail counts, % complete per phase, gates passed, and overall completion.
B13: Recommended workflow:
B14: • Hand Codex the matching phase prompt (TALARIA_PHASE_1_MVP.md, etc.) plus the reference PDF.
B15: • As Codex reports each piece done, set its Status here and spot-check against the acceptance criteria.
... B18: Component tally: ESSENTIALS 19 · EXCURSION 16 · WHAT-IF 5 · STATISTICAL 6 · PATTERNS 10 · STRATEGY HEALTH 3 · PROP CHALLENGE 5 · LIVE DISCIPLINE 3 · STRATEGY SOURCE 2 · EXPORT 2.
